Exception in thread NetStatThr:
Traceback (most recent call last):
  File "/usr/lib/python3.10/threading.py", line 1009, in _bootstrap_inner
    self.run()
  File "/usr/lib/python3.10/threading.py", line 946, in run
    self._target(*self._args, **self._kwargs)
  File "/home/baris/.local/lib/python3.10/site-packages/wandb/sdk/wandb_run.py", line 152, in check_network_status
    status_response = self._interface.communicate_network_status()
  File "/home/baris/.local/lib/python3.10/site-packages/wandb/sdk/interface/interface.py", line 138, in communicate_network_status
    resp = self._communicate_network_status(status)
  File "/home/baris/.local/lib/python3.10/site-packages/wandb/sdk/interface/interface_shared.py", line 405, in _communicate_network_status
    resp = self._communicate(req, local=True)
  File "/home/baris/.local/lib/python3.10/site-packages/wandb/sdk/interface/interface_shared.py", line 226, in _communicate
    return self._communicate_async(rec, local=local).get(timeout=timeout)
  File "/home/baris/.local/lib/python3.10/site-packages/wandb/sdk/interface/interface_shared.py", line 231, in _communicate_async
    raise Exception("The wandb backend process has shutdown")
